Workbook

Sheet Benchmark détaillé
A1: MARQUE / PRODUIT | B1: IMPULSE | C1: IMPULSE | D1: IMPULSE | E1: IMPULSE | F1: IMPULSE | G1: NUTRIPURE | H1: NUTRIPURE | I1: NUTRIPURE | J1: NUTRIMUSCLE | K1: NUTRIMUSCLE | L1: NUTRIMUSCLE | M1: NUTRIMUSCLE | N1: NUTRIMUSCLE | O1: NUTRIMUSCLE | P1: NUTRIMUSCLE | Q1: NUTRIMUSCLE | R1: NUTRI&CO | S1: NUTRI&CO | T1: AQEELAB | U1: ERIC FAVRE | V1: ERIC FAVRE | W1: ERIC FAVRE | X1: ERIC FAVRE | Y1: ERIC FAVRE | Z1: ERIC FAVRE | AA1: ERIC FAVRE | AB1: ERIC FAVRE | AC1: EAFIT | AD1: EAFIT | AE1: EAFIT | AF1: EAFIT | AG1: EAFIT | AH1: EAFIT | AI1: BULK | AJ1: BULK | AK1: BULK | AL1: BULK | AM1: BULK | AN1: BULK | AO1: MYPROTEIN | AP1: MYPROTEIN | AQ1: MYPROTEIN | AR1: MYPROTEIN | AS1: MYPROTEIN | AT1: MYPROTEIN | AU1: BIOTECHUSA | AV1: BIOTECHUSA | AW1: BIOTECHUSA | AX1: BIOTECHUSA | AY1: BIOTECHUSA
A2: RÉFÉRENCE | B2: Whey Isolate (750g chocolat) | C2: Whey Isolate (750g vanille) | D2: Whey Isolate (750g nature) | E2: Whey Recovery (525g chocolat) | F2: Whey Recovery (525g vanille) | G2: Whey Isolat Native 750g (750g chocolat) | H2: Whey Isolat Native 2kg (2kg chocolat) | I2: Whey Isolat Native 4kg (4kg chocolat) | J2: Whey Native Isolate 500g (500g chocolat) | K2: Whey Native Isolate (1kg chocolat) | L2: Whey Native Isolate 2,25kg (2.25kg chocolat) | M2: Whey Native Isolate 4kg (4kg chocolat) | N2: Whey Native Concentrat 500g (500g chocolat) | O2: Whey Native Concentrat (1kg chocolat) | P2: Whey Native Concentrat 2,25kg (2.25kg chocolat) | Q2: Whey Native Concentrat 4kg (4kg chocolat) | R2: Whey Isolate Native 900g (900g chocolat) | S2: Whey Concentrée Native 900g (900g chocolat) | T2: Whey Native 810g (810g chocolat) | U2: Iso Zero 100% Whey Protéine 500g (500g cookies cream) | V2: Iso Zero 100% Whey Protéine 1,5kg (1.5kg chocolat) | W2: Iso Zero 100% Whey Protéine 2kg (2kg chocotella) | X2: Whey Optimax Protein 500g (500g biscuit cookie) | Y2: Whey Optimax Protein 1,5kg (1.5kg chocolat) | Z2: Whey Zero Protéine 2kg (2kg chocolat) | AA2: Iso Fusion Protein Complex 750g (750g biscuit cookie) | AB2: Iso Fusion Protein Complex 2kg (2kg biscuit cookie) | AC2: Pure Isolate 750g (750g chocolat) | AD2: Pure Isolate Premium 750g (750g citron) | AE2: Pure Whey Protein 750g (750g double chocolat) | AF2: Mega Whey Creatine Complex 750g (750g chocolat) | AG2: Pure Whey Protein 850g (850g double chocolat) | AH2: Pure Whey Protein 2.2kg (2.2kg double chocolat) | AI2: Pure Whey Isolate 1kg (1kg chocolat) | AJ2: Pure Whey Isolate 2,5kg (2.5kg chocolat) | AK2: Pure Whey Protein 1kg (1kg chocolat) | AL2: Pure Whey Protein 2,5kg (2.5kg chocolat) | AM2: Pure Whey Protein 5kg (5kg chocolat) | AN2: Clear Whey Isolate 500g (500g fraise) | AO2: Impact Whey Isolate 1kg (1kg chocolat) | AP2: Impact Whey Isolate 2,5kg (2.5kg chocolat) | AQ2: Impact Whey Protein 1kg (1kg chocolat) | AR2: Impact Whey Protein 2,5kg (2.5kg chocolat) | AS2: Impact Whey Protein 5kg (Sans arôme) (5kg sans arôme) | AT2: Clear Whey Isolate 875g (875g fraise) | AU2: Iso Whey Zero 908g (908g chocolat) | AV2: Iso Whey Zero 1816g (1.816kg chocolat) | AW2: 100% Pure Whey 400g (400g chocolat) | AX2: 100% Pure Whey 1000g (1kg chocolat) | AY2: 100% Pure Whey 2000g (2kg chocolat)
A3: IDENTIFICATION
A4: Type de whey | B4: isolat natif (natif) | C4: isolat natif (natif) | D4: isolat natif (natif) | E4: concentrat fromagere | F4: concentrat fromagere | G4: isolat natif (natif) | H4: isolat natif (natif) | I4: isolat natif (natif) | J4: isolat natif (natif) | K4: isolat natif (natif) | L4: isolat natif (natif) | M4: isolat natif (natif) | N4: concentrat natif (natif) | O4: concentrat natif (natif) | P4: concentrat natif (natif) | Q4: concentrat natif (natif) | R4: isolat natif (natif) | S4: concentrat natif (natif) | T4: concentrat natif (natif) | U4: isolat fromagere | V4: isolat fromagere | W4: isolat fromagere | X4: concentrat fromagere | Y4: concentrat fromagere | Z4: concentrat fromagere | AA4: mix concentrat isolat | AB4: mix concentrat isolat | AC4: isolat fromagere | AD4: isolat fromagere | AE4: concentrat fromagere | AF4: concentrat fromagere | AG4: concentrat fromagere | AH4: concentrat fromagere | AI4: isolat fromagere | AJ4: isolat fromagere | AK4: concentrat fromagere | AL4: concentrat fromagere | AM4: concentrat fromagere | AN4: clear hydrolysat | AO4: isolat fromagere | AP4: isolat fromagere | AQ4: concentrat fromagere | AR4: concentrat fromagere | AS4: concentrat fromagere | AT4: clear hydrolysat | AU4: isolat fromagere | AV4: isolat fromagere | AW4: concentrat fromagere | AX4: concentrat fromagere | AY4: concentrat fromagere
A5: Poids net (g) | B5: 750 | C5: 750 | D5: 750 | E5: 525 | F5: 525 | G5: 750 | H5: 2000 | I5: 4000 | J5: 500 | K5: 1000 | L5: 2250 | M5: 4000 | N5: 500 | O5: 1000 | P5: 2250 | Q5: 4000 | R5: 900 | S5: 900 | T5: 810 | U5: 500 | V5: 1500 | W5: 2000 | X5: 500 | Y5: 1500 | Z5: 2000 | AA5: 750 | AB5: 2000 | AC5: 750 | AD5: 750 | AE5: 750 | AF5: 750 | AG5: 850 | AH5: 2200 | AI5: 1000 | AJ5: 2500 | AK5: 1000 | AL5: 2500 | AM5: 5000 | AN5: 500 | AO5: 1000 | AP5: 2500 | AQ5: 1000 | AR5: 2500 | AS5: 5000 | AT5: 875 | AU5: 908 | AV5: 1816 | AW5: 400 | AX5: 1000 | AY5: 2000
A6: Arôme pivot | B6: chocolat | C6: vanille | D6: nature | E6: chocolat | F6: vanille | G6: chocolat | H6: chocolat | I6: chocolat | J6: chocolat | K6: chocolat | L6: chocolat | M6: chocolat | N6: chocolat | O6: chocolat | P6: chocolat | Q6: chocolat | R6: chocolat | S6: chocolat | T6: chocolat | U6: cookies cream | V6: chocolat | W6: chocotella | X6: biscuit cookie | Y6: chocolat | Z6: chocolat | AA6: biscuit cookie | AB6: biscuit cookie | AC6: chocolat | AD6: citron | AE6: double chocolat | AF6: chocolat | AG6: double chocolat | AH6: double chocolat | AI6: chocolat | AJ6: chocolat | AK6: chocolat | AL6: chocolat | AM6: chocolat | AN6: fraise | AO6: chocolat | AP6: chocolat | AQ6: chocolat | AR6: chocolat | AS6: sans arôme | AT6: fraise | AU6: chocolat | AV6: chocolat | AW6: chocolat | AX6: chocolat | AY6: chocolat
A7: Arômes disponibles (sample) | B7: chocolat, vanille, nature | C7: chocolat, vanille, nature | D7: chocolat, vanille, nature | E7: chocolat, vanille | F7: chocolat, vanille | G7: Chocolat, Vanille, Neutre, Noisette, Fraise | H7: Chocolat, Vanille, Neutre, Noisette, Fraise | I7: chocolat, vanille, neutre, noisette, fraise | J7: chocolat, nature, vanille, choco cookie, fraise, banane | K7: Chocolat, Vanille, Neutre, Fraise | L7: chocolat, nature, vanille, choco cookie, fraise, banane | M7: chocolat, nature, vanille, choco cookie, fraise, banane | N7: chocolat, vanille, nature | O7: Chocolat, Vanille, Neutre, Fraise | P7: chocolat, vanille, nature | Q7: chocolat, vanille, nature | R7: chocolat, vanille, sans arôme | S7: chocolat, vanille | T7: chocolat, vanille | U7: chocolat, vanille, cookies cream, chocotella, pistache | V7: chocolat, vanille, cookies cream, chocotella, pistache, framboisier, café latte | W7: chocolat, vanille, cookies cream, chocotella, pistache, framboisier, café latte | X7: chocolat, vanille, biscuit cookie | Y7: chocolat, vanille, biscuit cookie, chocotella | Z7: chocolat, vanille, cookies cream | AA7: biscuit cookie, vanille, chocotella | AB7: biscuit cookie, vanille, chocotella | AC7: chocolat, vanille, fruits rouges | AD7: citron | AE7: double chocolat, café, chocolat noisette, vanille intense, caramel, fraise | AF7: chocolat, vanille | AG7: double chocolat, café, chocolat noisette, vanille intense, caramel | AH7: double chocolat, vanille intense, fraise, myrtille, chocolat noisette | AI7: Choco, Vanille, Fraise, Neutre | AJ7: Choco, Vanille, Fraise, Neutre | AK7: +20 saveurs (Choco, Vanille, Fraise, Neutre...) | AL7: +20 saveurs | AM7: +20 saveurs | AN7: Fraise, Pastèque, Pêche, Ananas... | AO7: +40 saveurs | AP7: +40 saveurs | AQ7: +40 saveurs (Choco Brownie, Vanille, Fraise, Neutre...) | AR7: +40 saveurs | AS7: sans arôme | AT7: Fraise, Pastèque, Limonade, Tropical... | AU7: chocolat, chocolat blanc, vanille, caramel catalan, banane, black biscuit | AV7: chocolat, chocolat blanc, vanille, caramel catalan, banane | AW7: chocolat, vanille bourbon, fraise, noisettes, beurre de cacahuète au chocolat, cookies & cream | AX7: chocolat, vanille bourbon, fraise, noisettes, cookies & cream | AY7: chocolat, vanille bourbon, fraise, noisettes, cookies & cream
A8: Origine lait | B8: France | C8: France | D8: France | E8: UE | F8: UE | G8: France (pâturages) | H8: France (pâturages) | I8: France (pâturages) | J8: France (Lactalis) | K8: France (Lactalis) | L8: France (Lactalis) | M8: France (Lactalis) | N8: France (Lactalis) | O8: France (Lactalis) | P8: France (Lactalis) | Q8: France (Lactalis) | R8: France | S8: France (pâturages) | T8: France | AI8: UE | AJ8: UE | AK8: UE | AL8: UE | AM8: UE | AN8: UE | AO8: UE | AP8: UE | AQ8: UE (UK, IE, NL...) | AR8: UE | AS8: UE | AT8: UE
A9: Certifications | E9: Creapure®, Peptan® | F9: Creapure®, Peptan® | G9: EN 17444 | H9: EN 17444 | I9: EN 17444 | J9: Certifié, lait Lactalis FR | K9: Certifié, lait Lactalis FR | L9: Certifié, lait Lactalis FR | M9: Certifié, lait Lactalis FR | N9: Certifié, lait Lactalis FR | O9: Certifié, lait Lactalis FR | P9: Certifié, lait Lactalis FR | Q9: Certifié, lait Lactalis FR | T9: Testée labo indépendant | U9: Nutricontrole | V9: Nutricontrole | W9: Nutricontrole | X9: Nutricontrole | Y9: Nutricontrole | Z9: Nutricontrole | AA9: Nutricontrole | AB9: Nutricontrole | AC9: Marque N°1 en pharmacie | AD9: Marque N°1 en pharmacie | AE9: Marque N°1 en pharmacie | AF9: Marque N°1 en pharmacie | AG9: Marque N°1 en pharmacie | AH9: Marque N°1 en pharmacie | AI9: Informed Sport | AJ9: Informed Sport | AK9: Informed Sport | AL9: Informed Sport | AM9: Informed Sport | AN9: Informed Sport | AO9: Informed Choice | AP9: Informed Choice | AQ9: Informed Choice | AR9: Informed Choice | AS9: Informed Choice | AT9: Informed Choice
A10: Native / Fromagère | B10: native | C10: native | D10: native | E10: fromagere | F10: fromagere | G10: native | H10: native | I10: native | J10: native | K10: native | L10: native | M10: native | N10: native | O10: native | P10: native | Q10: native | R10: native | S10: native | T10: native | U10: fromagere | V10: fromagere | W10: fromagere | X10: fromagere | Y10: fromagere | Z10: fromagere | AA10: fromagere | AB10: fromagere | AC10: fromagere | AD10: fromagere | AE10: fromagere | AF10: fromagere | AG10: fromagere | AH10: fromagere | AI10: fromagere | AJ10: fromagere | AK10: fromagere | AL10: fromagere | AM10: fromagere | AN10: fromagere | AO10: fromagere | AP10: fromagere | AQ10: fromagere | AR10: fromagere | AS10: fromagere | AT10: fromagere | AU10: fromagere | AV10: fromagere | AW10: fromagere | AX10: fromagere | AY10: fromagere
A11: FORMULE & NUTRITION
A12: % protéines / 100g | B12: 85 | C12: 85 | D12: 85 | E12: 60 | F12: 60 | G12: 94 | H12: 94 | I12: 85 | J12: 87 | K12: 85 | L12: 87 | M12: 87 | N12: 80 | O12: 80 | P12: 80 | Q12: 80 | R12: 94 | S12: 75 | T12: 94 | U12: 83 | V12: 83 | W12: 83 | X12: 73 | Y12: 73 | Z12: 75 | AA12: 81 | AB12: 81 | AC12: 81 | AD12: 79 | AE12: 77 | AF12: 73 | AG12: 77 | AH12: 77 | AI12: 90 | AJ12: 90 | AK12: 82 | AL12: 82 | AM12: 82 | AN12: 72 | AO12: 90 | AP12: 90 | AQ12: 82 | AR12: 82 | AS12: 82 | AT12: 68 | AU12: 84 | AV12: 84 | AW12: 76 | AX12: 76 | AY12: 76
A13: Protéines / portion (g) | B13: 25.5 | C13: 25.5 | D13: 25.5 | E13: 21 | F13: 21 | G13: 25 | H13: 25 | I13: 25 | J13: 25 | K13: 24 | L13: 25 | M13: 25 | N13: 24 | O13: 24 | P13: 24 | Q13: 24 | R13: 28 | S13: 22.1 | T13: 28.2 | U13: 25 | V13: 25 | W13: 25 | X13: 22 | Y13: 22 | Z13: 22.5 | AA13: 24.4 | AB13: 24.4 | AC13: 25 | AD13: 24 | AE13: 31 | AF13: 44 | AG13: 31 | AH13: 31 | AI13: 26 | AJ13: 26 | AK13: 22 | AL13: 22 | AM13: 22 | AN13: 20 | AO13: 25 | AP13: 25 | AQ13: 23 | AR13: 23 | AS13: 23 | AT13: 20 | AU13: 21 | AV13: 21 | AW13: 21 | AX13: 21 | AY13: 21
A14: Taille portion (g) | B14: 30 | C14: 30 | D14: 30 | E14: 35 | F14: 35 | G14: 30 | H14: 30 | I14: 30 | J14: 30 | K14: 30 | L14: 30 | M14: 30 | N14: 30 | O14: 30 | P14: 30 | Q14: 30 | R14: 30 | S14: 30 | T14: 30 | U14: 30 | V14: 30 | W14: 30 | X14: 30 | Y14: 30 | Z14: 30 | AA14: 30 | AB14: 30 | AC14: 30 | AD14: 30 | AE14: 40 | AF14: 60 | AG14: 40 | AH14: 40 | AI14: 30 | AJ14: 30 | AK14: 30 | AL14: 30 | AM14: 30 | AN14: 30 | AO14: 25 | AP14: 25 | AQ14: 25 | AR14: 25 | AS14: 25 | AT14: 25 | AU14: 25 | AV14: 25 | AW14: 30 | AX14: 30 | AY14: 30
A15: Nb portions / format | B15: 25 | C15: 25 | D15: 25 | E15: 15 | F15: 15 | G15: 25 | H15: 66 | I15: 133 | J15: 16 | K15: 33 | L15: 75 | M15: 133 | N15: 16 | O15: 33 | P15: 75 | Q15: 133 | R15: 30 | S15: 30 | T15: 27 | U15: 16 | V15: 50 | W15: 66 | X15: 16 | Y15: 50 | Z15: 66 | AA15: 25 | AB15: 66 | AC15: 25 | AD15: 25 | AE15: 19 | AF15: 12 | AG15: 21 | AH15: 55 | AI15: 33 | AJ15: 83 | AK15: 33 | AL15: 83 | AM15: 166 | AN15: 16 | AO15: 40 | AP15: 100 | AQ15: 40 | AR15: 100 | AS15: 200 | AT15: 35 | AU15: 36 | AV15: 72 | AW15: 13 | AX15: 33 | AY15: 66
A16: BCAA / portion (g) | B16: 5.3 | C16: 5.3 | D16: 5.3 | G16: 5 | H16: 5 | I16: 5 | J16: 6 | K16: 6 | L16: 6 | M16: 6 | N16: 5 | O16: 5 | P16: 5 | Q16: 5 | R16: 6.9 | S16: 5.1 | T16: 6.6 | U16: 5.66 | V16: 5.66 | W16: 5.66 | X16: 3.74 | Y16: 3.74 | AA16: 4.1 | AB16: 4.1 | AC16: 5.5 | AD16: 5.2 | AE16: 7 | AF16: 10 | AG16: 7 | AH16: 7 | AI16: 5.5 | AJ16: 5.5 | AK16: 5 | AL16: 5 | AM16: 5 | AN16: 4 | AO16: 5.5 | AP16: 5.5 | AQ16: 4.5 | AR16: 4.5 | AS16: 4.5 | AT16: 4 | AU16: 4.35 | AV16: 4.35
A17: Glucides / portion (g) | B17: 1 | C17: 1 | D17: 1 | G17: 0.3 | H17: 0.3 | I17: 0.3 | J17: 1.5 | K17: 1.5 | L17: 1.5 | M17: 1.5 | N17: 3.5 | O17: 3.5 | P17: 3.5 | Q17: 3.5 | R17: 0.9 | S17: 4 | T17: 0.5 | U17: 0.5 | V17: 0.5 | W17: 0.5 | Z17: 3 | AA17: 1.4 | AB17: 1.4 | AC17: 1.4 | AD17: 0.5 | AE17: 4 | AF17: 4.3 | AG17: 4 | AH17: 4 | AI17: 1.5 | AJ17: 1.5 | AK17: 2 | AL17: 2 | AM17: 2 | AN17: 0.5 | AO17: 1 | AP17: 1 | AQ17: 2 | AR17: 2 | AS17: 2 | AT17: 0.5 | AU17: 0.6 | AV17: 0.6 | AW17: 1.4 | AX17: 1.4 | AY17: 1.4
A18: Lipides / portion (g) | B18: 0.5 | C18: 0.5 | D18: 0.5 | G18: 0.2 | H18: 0.2 | I18: 0.2 | J18: 0.8 | K18: 0.8 | L18: 0.8 | M18: 0.8 | N18: 1.5 | O18: 1.5 | P18: 1.5 | Q18: 1.5 | R18: 0.6 | S18: 0.4 | T18: 0.4 | U18: 0.4 | V18: 0.4 | W18: 0.4 | Z18: 1.4 | AA18: 1.6 | AB18: 1.6 | AC18: 0.5 | AD18: 0.3 | AE18: 1.7 | AF18: 2 | AG18: 1.7 | AH18: 1.7 | AI18: 0.5 | AJ18: 0.5 | AK18: 1 | AL18: 1 | AM18: 1 | AN18: 0.1 | AO18: 0.5 | AP18: 0.5 | AQ18: 1 | AR18: 1 | AS18: 1 | AT18: 0.1 | AU18: 0.4 | AV18: 0.4 | AW18: 1.8 | AX18: 1.8 | AY18: 1.8
A19: Lactose | B19: faible | C19: faible | D19: faible | E19: present | F19: present | G19: tres_faible | H19: tres_faible | I19: tres_faible | J19: faible | K19: faible | L19: faible | M19: faible | N19: present | O19: present | P19: present | Q19: present | R19: tres_faible | S19: faible | T19: faible | U19: tres_faible | V19: tres_faible | W19: tres_faible | AA19: faible | AB19: faible | AC19: tres_faible | AD19: tres_faible | AF19: present | AI19: faible | AJ19: faible | AK19: present | AL19: present | AM19: present | AN19: tres_faible | AO19: faible | AP19: faible | AQ19: present | AR19: present | AS19: present | AT19: tres_faible | AU19: tres_faible | AV19: tres_faible
A20: PRIX — 3 COUCHES (nominal / current / marché médian)
A21: Prix nominal (site propre, barré) | B21: 39.9 | C21: 39.9 | D21: 37.9 | E21: 39.9 | F21: 39.9 | G21: 39.9 | H21: 104.9 | I21: 179.9 | J21: 31.95 | K21: 57.95 | L21: 116.95 | M21: 190.95 | N21: 19.95 | O21: 37.95 | P21: 80.95 | Q21: 131.95 | R21: 54.9 | S21: 39.9 | T21: 45.95 | U21: 33.9 | V21: 79.9 | W21: 94.9 | X21: 29.9 | Y21: 59.9 | Z21: 82.9 | AA21: 41.9 | AB21: 65.9 | AC21: 45.9 | AD21: 45.9 | AE21: 34.9 | AF21: 39.99 | AG21: 38.9 | AH21: 80.99 | AI21: 69.99 | AJ21: 159.99 | AK21: 37.99 | AL21: 84.99 | AM21: 159.99 | AN21: 31.49 | AO21: 57.99 | AP21: 124.99 | AQ21: 41.99 | AR21: 84.99 | AS21: 188.99 | AT21: 49.99 | AU21: 69.9 | AV21: 104.9 | AW21: 32.9 | AX21: 54.9 | AY21: 89.9
A22: Prix actuel (site propre, affiché) | B22: 39.9 | C22: 39.9 | D22: 37.9 | E22: 39.9 | F22: 39.9 | G22: 39.9 | H22: 104.9 | I22: 179.9 | J22: 31.95 | K22: 57.95 | L22: 116.95 | M22: 190.95 | N22: 19.95 | O22: 37.95 | P22: 80.95 | Q22: 131.95 | R22: 54.9 | S22: 39.9 | T22: 45.95 | U22: 33.9 | V22: 79.9 | W22: 94.9 | X22: 29.9 | Y22: 59.9 | Z22: 82.9 | AA22: 41.9 | AB22: 65.9 | AC22: 45.9 | AD22: 45.9 | AE22: 34.9 | AF22: 39.99 | AG22: 38.9 | AH22: 80.99 | AI22: 44.99 | AJ22: 99.99 | AK22: 27.99 | AL22: 64.99 | AM22: 129.99 | AN22: 25.99 | AO22: 57.99 | AP22: 124.99 | AQ22: 17.99 | AR22: 40.99 | AS22: 91.1 | AT22: 49.99 | AU22: 69.9 | AV22: 104.9 | AW22: 32.9 | AX22: 54.9 | AY22: 89.9
A23: Prix médian marché (idealo/ledenicheur) | AK23: 23.99 | AN23: 22.25 | AO23: 56.4 | AQ23: 34.99 | AR23: 56.4 | AS23: 188.99 | AX23: 27.02
A24: Écart nominal → actuel (%) | B24: =IFERROR((B21-B22)/B21*100,"") | C24: =IFERROR((C21-C22)/C21*100,"") | D24: =IFERROR((D21-D22)/D21*100,"") | E24: =IFERROR((E21-E22)/E21*100,"") | F24: =IFERROR((F21-F22)/F21*100,"") | G24: =IFERROR((G21-G22)/G21*100,"") | H24: =IFERROR((H21-H22)/H21*100,"") | I24: =IFERROR((I21-I22)/I21*100,"") | ... AY24: =IFERROR((AY21-AY22)/AY21*100,"")
A25: Écart actuel → marché (%) | B25: =IFERROR((B22-B23)/B22*100,"") | C25: =IFERROR((C22-C23)/C22*100,"") | D25: =IFERROR((D22-D23)/D22*100,"") | E25: =IFERROR((E22-E23)/E22*100,"") | F25: =IFERROR((F22-F23)/F22*100,"") | G25: =IFERROR((G22-G23)/G22*100,"") | H25: =IFERROR((H22-H23)/H22*100,"") | I25: =IFERROR((I22-I23)/I22*100,"") | ... AY25: =IFERROR((AY22-AY23)/AY22*100,"")
A26: PRIX DÉRIVÉS (base = prix actuel site propre)
A27: Prix actuel / kg (€) | B27: =IFERROR(B22/(B5/1000),"") | C27: =IFERROR(C22/(C5/1000),"") | D27: =IFERROR(D22/(D5/1000),"") | E27: =IFERROR(E22/(E5/1000),"") | F27: =IFERROR(F22/(F5/1000),"") | G27: =IFERROR(G22/(G5/1000),"") | H27: =IFERROR(H22/(H5/1000),"") | I27: =IFERROR(I22/(I5/1000),"") | ... AY27: =IFERROR(AY22/(AY5/1000),"")
A28: Prix actuel / portion (€) | B28: =IFERROR(B22/B15,"") | C28: =IFERROR(C22/C15,"") | D28: =IFERROR(D22/D15,"") | E28: =IFERROR(E22/E15,"") | F28: =IFERROR(F22/F15,"") | G28: =IFERROR(G22/G15,"") | H28: =IFERROR(H22/H15,"") | I28: =IFERROR(I22/I15,"") | ... AY28: =IFERROR(AY22/AY15,"")
A29: Prix actuel / g de protéine (€) | B29: =IFERROR(B22/(B15*B13),"") | C29: =IFERROR(C22/(C15*C13),"") | D29: =IFERROR(D22/(D15*D13),"") | E29: =IFERROR(E22/(E15*E13),"") | F29: =IFERROR(F22/(F15*F13),"") | G29: =IFERROR(G22/(G15*G13),"") | H29: =IFERROR(H22/(H15*H13),"") | I29: =IFERROR(I22/(I15*I13),"") | ... AY29: =IFERROR(AY22/(AY15*AY13),"")
A30: Prix marché / g de protéine (€) | B30: =IFERROR(B23/(B15*B13),"") | C30: =IFERROR(C23/(C15*C13),"") | D30: =IFERROR(D23/(D15*D13),"") | E30: =IFERROR(E23/(E15*E13),"") | F30: =IFERROR(F23/(F15*F13),"") | G30: =IFERROR(G23/(G15*G13),"") | H30: =IFERROR(H23/(H15*H13),"") | I30: =IFERROR(I23/(I15*I13),"") | ... AY30: =IFERROR(AY23/(AY15*AY13),"")
A31: Prix abonnement (€ TTC) | T31: 36.76
A32: Remise abo (%) | T32: 20
A33: PRIX EFFECTIF (avec code influenceur appliqué sur prix actuel)
A34: Remise bas fourchette (%) | B34: =IFERROR(VLOOKUP(B1,'Discounts par marque'!$A:$G,3,FALSE),0) | C34: =IFERROR(VLOOKUP(C1,'Discounts par marque'!$A:$G,3,FALSE),0) | D34: =IFERROR(VLOOKUP(D1,'Discounts par marque'!$A:$G,3,FALSE),0) | E34: =IFERROR(VLOOKUP(E1,'Discounts par marque'!$A:$G,3,FALSE),0) | F34: =IFERROR(VLOOKUP(F1,'Discounts par marque'!$A:$G,3,FALSE),0) | G34: =IFERROR(VLOOKUP(G1,'Discounts par marque'!$A:$G,3,FALSE),0) | H34: =IFERROR(VLOOKUP(H1,'Discounts par marque'!$A:$G,3,FALSE),0) | I34: =IFERROR(VLOOKUP(I1,'Discounts par marque'!$A:$G,3,FALSE),0) | ... AY34: =IFERROR(VLOOKUP(AY1,'Discounts par marque'!$A:$G,3,FALSE),0)
A35: Remise client standard (%) | B35: =IFERROR(VLOOKUP(B1,'Discounts par marque'!$A:$G,4,FALSE),0) | C35: =IFERROR(VLOOKUP(C1,'Discounts par marque'!$A:$G,4,FALSE),0) | D35: =IFERROR(VLOOKUP(D1,'Discounts par marque'!$A:$G,4,FALSE),0) | E35: =IFERROR(VLOOKUP(E1,'Discounts par marque'!$A:$G,4,FALSE),0) | F35: =IFERROR(VLOOKUP(F1,'Discounts par marque'!$A:$G,4,FALSE),0) | G35: =IFERROR(VLOOKUP(G1,'Discounts par marque'!$A:$G,4,FALSE),0) | H35: =IFERROR(VLOOKUP(H1,'Discounts par marque'!$A:$G,4,FALSE),0) | I35: =IFERROR(VLOOKUP(I1,'Discounts par marque'!$A:$G,4,FALSE),0) | ... AY35: =IFERROR(VLOOKUP(AY1,'Discounts par marque'!$A:$G,4,FALSE),0)
A36: Remise client averti (%) | B36: =IFERROR(VLOOKUP(B1,'Discounts par marque'!$A:$G,5,FALSE),0) | C36: =IFERROR(VLOOKUP(C1,'Discounts par marque'!$A:$G,5,FALSE),0) | D36: =IFERROR(VLOOKUP(D1,'Discounts par marque'!$A:$G,5,FALSE),0) | E36: =IFERROR(VLOOKUP(E1,'Discounts par marque'!$A:$G,5,FALSE),0) | F36: =IFERROR(VLOOKUP(F1,'Discounts par marque'!$A:$G,5,FALSE),0) | G36: =IFERROR(VLOOKUP(G1,'Discounts par marque'!$A:$G,5,FALSE),0) | H36: =IFERROR(VLOOKUP(H1,'Discounts par marque'!$A:$G,5,FALSE),0) | I36: =IFERROR(VLOOKUP(I1,'Discounts par marque'!$A:$G,5,FALSE),0) | ... AY36: =IFERROR(VLOOKUP(AY1,'Discounts par marque'!$A:$G,5,FALSE),0)
A37: Remise plafond observé (%) | B37: =IFERROR(VLOOKUP(B1,'Discounts par marque'!$A:$G,6,FALSE),0) | C37: =IFERROR(VLOOKUP(C1,'Discounts par marque'!$A:$G,6,FALSE),0) | D37: =IFERROR(VLOOKUP(D1,'Discounts par marque'!$A:$G,6,FALSE),0) | E37: =IFERROR(VLOOKUP(E1,'Discounts par marque'!$A:$G,6,FALSE),0) | F37: =IFERROR(VLOOKUP(F1,'Discounts par marque'!$A:$G,6,FALSE),0) | G37: =IFERROR(VLOOKUP(G1,'Discounts par marque'!$A:$G,6,FALSE),0) | H37: =IFERROR(VLOOKUP(H1,'Discounts par marque'!$A:$G,6,FALSE),0) | I37: =IFERROR(VLOOKUP(I1,'Discounts par marque'!$A:$G,6,FALSE),0) | ... AY37: =IFERROR(VLOOKUP(AY1,'Discounts par marque'!$A:$G,6,FALSE),0)
A38: Prix client standard (€) | B38: =IFERROR(B22*(1-B35/100),"") | C38: =IFERROR(C22*(1-C35/100),"") | D38: =IFERROR(D22*(1-D35/100),"") | E38: =IFERROR(E22*(1-E35/100),"") | F38: =IFERROR(F22*(1-F35/100),"") | G38: =IFERROR(G22*(1-G35/100),"") | H38: =IFERROR(H22*(1-H35/100),"") | I38: =IFERROR(I22*(1-I35/100),"") | ... AY38: =IFERROR(AY22*(1-AY35/100),"")
A39: Prix client averti (€) | B39: =IFERROR(B22*(1-B36/100),"") | C39: =IFERROR(C22*(1-C36/100),"") | D39: =IFERROR(D22*(1-D36/100),"") | E39: =IFERROR(E22*(1-E36/100),"") | F39: =IFERROR(F22*(1-F36/100),"") | G39: =IFERROR(G22*(1-G36/100),"") | H39: =IFERROR(H22*(1-H36/100),"") | I39: =IFERROR(I22*(1-I36/100),"") | ... AY39: =IFERROR(AY22*(1-AY36/100),"")
A40: Prix plafond (€) | B40: =IFERROR(B22*(1-B37/100),"") | C40: =IFERROR(C22*(1-C37/100),"") | D40: =IFERROR(D22*(1-D37/100),"") | E40: =IFERROR(E22*(1-E37/100),"") | F40: =IFERROR(F22*(1-F37/100),"") | G40: =IFERROR(G22*(1-G37/100),"") | H40: =IFERROR(H22*(1-H37/100),"") | I40: =IFERROR(I22*(1-I37/100),"") | ... AY40: =IFERROR(AY22*(1-AY37/100),"")
...

Sheet Synthèse prix
A1: Marque | B1: Produit | C1: Type | D1: Natif/Fromagère | E1: Format (g) | F1: Nb portions | G1: Prot/portion (g) | H1: Prix nominal (€) | I1: Prix actuel (€) | J1: Prix marché (€) | K1: Gap nominal→actuel (%) | L1: Gap actuel→marché (%) | M1: Prix actuel /kg | N1: Prix actuel /g prot | O1: Prix abo (€) | P1: % abo | Q1: Remise client standard (%) | R1: Remise client averti (%) | S1: Prix client standard (€) | T1: Prix client standard /g prot | U1: Prix client averti (€) | V1: Prix client averti /g prot | W1: Source URL | X1: Gap note
A2: ='Benchmark détaillé'!B1 | B2: Whey Isolate | C2: ='Benchmark détaillé'!B4 | D2: ='Benchmark détaillé'!B10 | E2: ='Benchmark détaillé'!B5 | F2: ='Benchmark détaillé'!B15 | G2: ='Benchmark détaillé'!B13 | H2: ='Benchmark détaillé'!B21 | I2: ='Benchmark détaillé'!B22 | J2: ='Benchmark détaillé'!B23 | K2: =IFERROR((H2-I2)/H2*100,"") | L2: =IFERROR((I2-J2)/I2*100,"") | M2: =IFERROR(I2/(E2/1000),"") | N2: =IFERROR(I2/(F2*G2),"") | O2: ='Benchmark détaillé'!B31 | P2: ='Benchmark détaillé'!B32 | Q2: =IFERROR(VLOOKUP(A2,'Discounts par marque'!$A:$G,4,FALSE),0) | R2: =IFERROR(VLOOKUP(A2,'Discounts par marque'!$A:$G,5,FALSE),0) | S2: =IFERROR(I2*(1-Q2/100),"") | T2: =IFERROR(S2/(F2*G2),"") | U2: =IFERROR(I2*(1-R2/100),"") | V2: =IFERROR(U2/(F2*G2),"") | W2: https://impulse-nutrition.fr/products/whey-isolate-saveur-chocolat
A3: ='Benchmark détaillé'!C1 | B3: Whey Isolate | C3: ='Benchmark détaillé'!C4 | D3: ='Benchmark détaillé'!C10 | E3: ='Benchmark détaillé'!C5 | F3: ='Benchmark détaillé'!C15 | G3: ='Benchmark détaillé'!C13 | H3: ='Benchmark détaillé'!C21 | I3: ='Benchmark détaillé'!C22 | J3: ='Benchmark détaillé'!C23 | K3: =IFERROR((H3-I3)/H3*100,"") | L3: =IFERROR((I3-J3)/I3*100,"") | M3: =IFERROR(I3/(E3/1000),"") | N3: =IFERROR(I3/(F3*G3),"") | O3: ='Benchmark détaillé'!C31 | P3: ='Benchmark détaillé'!C32 | Q3: =IFERROR(VLOOKUP(A3,'Discounts par marque'!$A:$G,4,FALSE),0) | R3: =IFERROR(VLOOKUP(A3,'Discounts par marque'!$A:$G,5,FALSE),0) | S3: =IFERROR(I3*(1-Q3/100),"") | T3: =IFERROR(S3/(F3*G3),"") | U3: =IFERROR(I3*(1-R3/100),"") | V3: =IFERROR(U3/(F3*G3),"") | W3: https://impulse-nutrition.fr/products/whey-isolate-saveur-vanille
A4: ='Benchmark détaillé'!D1 | B4: Whey Isolate | C4: ='Benchmark détaillé'!D4 | D4: ='Benchmark détaillé'!D10 | E4: ='Benchmark détaillé'!D5 | F4: ='Benchmark détaillé'!D15 | G4: ='Benchmark détaillé'!D13 | H4: ='Benchmark détaillé'!D21 | I4: ='Benchmark détaillé'!D22 | J4: ='Benchmark détaillé'!D23 | K4: =IFERROR((H4-I4)/H4*100,"") | L4: =IFERROR((I4-J4)/I4*100,"") | M4: =IFERROR(I4/(E4/1000),"") | N4: =IFERROR(I4/(F4*G4),"") | O4: ='Benchmark détaillé'!D31 | P4: ='Benchmark détaillé'!D32 | Q4: =IFERROR(VLOOKUP(A4,'Discounts par marque'!$A:$G,4,FALSE),0) | R4: =IFERROR(VLOOKUP(A4,'Discounts par marque'!$A:$G,5,FALSE),0) | S4: =IFERROR(I4*(1-Q4/100),"") | T4: =IFERROR(S4/(F4*G4),"") | U4: =IFERROR(I4*(1-R4/100),"") | V4: =IFERROR(U4/(F4*G4),"") | W4: https://impulse-nutrition.fr/products/whey-isolate-nature
A5: ='Benchmark détaillé'!E1 | B5: Whey Recovery | C5: ='Benchmark détaillé'!E4 | D5: ='Benchmark détaillé'!E10 | E5: ='Benchmark détaillé'!E5 | F5: ='Benchmark détaillé'!E15 | G5: ='Benchmark détaillé'!E13 | H5: ='Benchmark détaillé'!E21 | I5: ='Benchmark détaillé'!E22 | J5: ='Benchmark détaillé'!E23 | K5: =IFERROR((H5-I5)/H5*100,"") | L5: =IFERROR((I5-J5)/I5*100,"") | M5: =IFERROR(I5/(E5/1000),"") | N5: =IFERROR(I5/(F5*G5),"") | O5: ='Benchmark détaillé'!E31 | P5: ='Benchmark détaillé'!E32 | Q5: =IFERROR(VLOOKUP(A5,'Discounts par marque'!$A:$G,4,FALSE),0) | R5: =IFERROR(VLOOKUP(A5,'Discounts par marque'!$A:$G,5,FALSE),0) | S5: =IFERROR(I5*(1-Q5/100),"") | T5: =IFERROR(S5/(F5*G5),"") | U5: =IFERROR(I5*(1-R5/100),"") | V5: =IFERROR(U5/(F5*G5),"") | W5: https://impulse-nutrition.fr/products/whey-recovery-saveur-chocolat | X5: Blend recovery (concentrat whey + créatine Creapure 3g + collagène Peptan 5g + magnésium). Pas comparable 1-pour-1 aux whey pures — 60% protéines car le reste = additifs de récupération.
A6: ='Benchmark détaillé'!F1 | B6: Whey Recovery | C6: ='Benchmark détaillé'!F4 | D6: ='Benchmark détaillé'!F10 | E6: ='Benchmark détaillé'!F5 | F6: ='Benchmark détaillé'!F15 | G6: ='Benchmark détaillé'!F13 | H6: ='Benchmark détaillé'!F21 | I6: ='Benchmark détaillé'!F22 | J6: ='Benchmark détaillé'!F23 | K6: =IFERROR((H6-I6)/H6*100,"") | L6: =IFERROR((I6-J6)/I6*100,"") | M6: =IFERROR(I6/(E6/1000),"") | N6: =IFERROR(I6/(F6*G6),"") | O6: ='Benchmark détaillé'!F31 | P6: ='Benchmark détaillé'!F32 | Q6: =IFERROR(VLOOKUP(A6,'Discounts par marque'!$A:$G,4,FALSE),0) | R6: =IFERROR(VLOOKUP(A6,'Discounts par marque'!$A:$G,5,FALSE),0) | S6: =IFERROR(I6*(1-Q6/100),"") | T6: =IFERROR(S6/(F6*G6),"") | U6: =IFERROR(I6*(1-R6/100),"") | V6: =IFERROR(U6/(F6*G6),"") | W6: https://impulse-nutrition.fr/products/whey-recovery-saveur-vanille | X6: Blend recovery (concentrat whey + créatine Creapure 3g + collagène Peptan 5g + magnésium). Pas comparable 1-pour-1 aux whey pures — 60% protéines car le reste = additifs de récupération.
A7: ='Benchmark détaillé'!G1 | B7: Whey Isolat Native 750g | C7: ='Benchmark détaillé'!G4 | D7: ='Benchmark détaillé'!G10 | E7: ='Benchmark détaillé'!G5 | F7: ='Benchmark détaillé'!G15 | G7: ='Benchmark détaillé'!G13 | H7: ='Benchmark détaillé'!G21 | I7: ='Benchmark détaillé'!G22 | J7: ='Benchmark détaillé'!G23 | K7: =IFERROR((H7-I7)/H7*100,"") | L7: =IFERROR((I7-J7)/I7*100,"") | M7: =IFERROR(I7/(E7/1000),"") | N7: =IFERROR(I7/(F7*G7),"") | O7: ='Benchmark détaillé'!G31 | P7: ='Benchmark détaillé'!G32 | Q7: =IFERROR(VLOOKUP(A7,'Discounts par marque'!$A:$G,4,FALSE),0) | R7: =IFERROR(VLOOKUP(A7,'Discounts par marque'!$A:$G,5,FALSE),0) | S7: =IFERROR(I7*(1-Q7/100),"") | T7: =IFERROR(S7/(F7*G7),"") | U7: =IFERROR(I7*(1-R7/100),"") | V7: =IFERROR(U7/(F7*G7),"") | W7: https://www.nutripure.fr/produits/whey-isolat-native-chocolat | X7: Prix marché = null (Nutripure vend uniquement sur site propre, pas de cross-retailers significatifs). Ancien 46€ sourcé via robshop.fr était un revendeur cher, pas un vrai marché médian.
A8: ='Benchmark détaillé'!H1 | B8: Whey Isolat Native 2kg | C8: ='Benchmark détaillé'!H4 | D8: ='Benchmark détaillé'!H10 | E8: ='Benchmark détaillé'!H5 | F8: ='Benchmark détaillé'!H15 | G8: ='Benchmark détaillé'!H13 | H8: ='Benchmark détaillé'!H21 | I8: ='Benchmark détaillé'!H22 | J8: ='Benchmark détaillé'!H23 | K8: =IFERROR((H8-I8)/H8*100,"") | L8: =IFERROR((I8-J8)/I8*100,"") | M8: =IFERROR(I8/(E8/1000),"") | N8: =IFERROR(I8/(F8*G8),"") | O8: ='Benchmark détaillé'!H31 | P8: ='Benchmark détaillé'!H32 | Q8: =IFERROR(VLOOKUP(A8,'Discounts par marque'!$A:$G,4,FALSE),0) | R8: =IFERROR(VLOOKUP(A8,'Discounts par marque'!$A:$G,5,FALSE),0) | S8: =IFERROR(I8*(1-Q8/100),"") | T8: =IFERROR(S8/(F8*G8),"") | U8: =IFERROR(I8*(1-R8/100),"") | V8: =IFERROR(U8/(F8*G8),"") | W8: https://www.nutripure.fr/fr/musculation/147-1115-whey-chocolat-isolate.html#/332-poids_poudre-seau_2kg | X8: Confirmé via Playwright click sur variant radio Seau 2KG (id=332). Page nutripure.fr. Agent v2 avait mal lu '90€' (probablement le 'à partir de' affiché sur la page parent).
A9: ='Benchmark détaillé'!I1 | B9: Whey Isolat Native 4kg | C9: ='Benchmark détaillé'!I4 | D9: ='Benchmark détaillé'!I10 | E9: ='Benchmark détaillé'!I5 | F9: ='Benchmark détaillé'!I15 | G9: ='Benchmark détaillé'!I13 | H9: ='Benchmark détaillé'!I21 | I9: ='Benchmark détaillé'!I22 | J9: ='Benchmark détaillé'!I23 | K9: =IFERROR((H9-I9)/H9*100,"") | L9: =IFERROR((I9-J9)/I9*100,"") | M9: =IFERROR(I9/(E9/1000),"") | N9: =IFERROR(I9/(F9*G9),"") | O9: ='Benchmark détaillé'!I31 | P9: ='Benchmark détaillé'!I32 | Q9: =IFERROR(VLOOKUP(A9,'Discounts par marque'!$A:$G,4,FALSE),0) | R9: =IFERROR(VLOOKUP(A9,'Discounts par marque'!$A:$G,5,FALSE),0) | S9: =IFERROR(I9*(1-Q9/100),"") | T9: =IFERROR(S9/(F9*G9),"") | U9: =IFERROR(I9*(1-R9/100),"") | V9: =IFERROR(U9/(F9*G9),"") | W9: https://www.nutripure.fr/fr/musculation/147-674-whey-chocolat-isolate.html#/47-poids_poudre-seau_4kg | X9: Confirmé via Playwright click sur variant radio Seau 4KG (id=47). Prix réel 179,90€ (pas 159,90€ extrapolé).
A10: ='Benchmark détaillé'!J1 | B10: Whey Native Isolate 500g | C10: ='Benchmark détaillé'!J4 | D10: ='Benchmark détaillé'!J10 | E10: ='Benchmark détaillé'!J5 | F10: ='Benchmark détaillé'!J15 | G10: ='Benchmark détaillé'!J13 | H10: ='Benchmark détaillé'!J21 | I10: ='Benchmark détaillé'!J22 | J10: ='Benchmark détaillé'!J23 | K10: =IFERROR((H10-I10)/H10*100,"") | L10: =IFERROR((I10-J10)/I10*100,"") | M10: =IFERROR(I10/(E10/1000),"") | N10: =IFERROR(I10/(F10*G10),"") | O10: ='Benchmark détaillé'!J31 | P10: ='Benchmark détaillé'!J32 | Q10: =IFERROR(VLOOKUP(A10,'Discounts par marque'!$A:$G,4,FALSE),0) | R10: =IFERROR(VLOOKUP(A10,'Discounts par marque'!$A:$G,5,FALSE),0) | S10: =IFERROR(I10*(1-Q10/100),"") | T10: =IFERROR(S10/(F10*G10),"") | U10: =IFERROR(I10*(1-R10/100),"") | V10: =IFERROR(U10/(F10*G10),"") | W10: https://www.nutrimuscle.com/products/whey-native-isolate
A11: ='Benchmark détaillé'!K1 | B11: Whey Native Isolate | C11: ='Benchmark détaillé'!K4 | D11: ='Benchmark détaillé'!K10 | E11: ='Benchmark détaillé'!K5 | F11: ='Benchmark détaillé'!K15 | G11: ='Benchmark détaillé'!K13 | H11: ='Benchmark détaillé'!K21 | I11: ='Benchmark détaillé'!K22 | J11: ='Benchmark détaillé'!K23 | K11: =IFERROR((H11-I11)/H11*100,"") | L11: =IFERROR((I11-J11)/I11*100,"") | M11: =IFERROR(I11/(E11/1000),"") | N11: =IFERROR(I11/(F11*G11),"") | O11: ='Benchmark détaillé'!K31 | P11: ='Benchmark détaillé'!K32 | Q11: =IFERROR(VLOOKUP(A11,'Discounts par marque'!$A:$G,4,FALSE),0) | R11: =IFERROR(VLOOKUP(A11,'Discounts par marque'!$A:$G,5,FALSE),0) | S11: =IFERROR(I11*(1-Q11/100),"") | T11: =IFERROR(S11/(F11*G11),"") | U11: =IFERROR(I11*(1-R11/100),"") | V11: =IFERROR(U11/(F11*G11),"") | W11: https://www.nutrimuscle.com/products/whey-isolat-native | X11: v1 avait 39.95€ (+45% correction)
A12: ='Benchmark détaillé'!L1 | B12: Whey Native Isolate 2,25kg | C12: ='Benchmark détaillé'!L4 | D12: ='Benchmark détaillé'!L10 | E12: ='Benchmark détaillé'!L5 | F12: ='Benchmark détaillé'!L15 | G12: ='Benchmark détaillé'!L13 | H12: ='Benchmark détaillé'!L21 | I12: ='Benchmark détaillé'!L22 | J12: ='Benchmark détaillé'!L23 | K12: =IFERROR((H12-I12)/H12*100,"") | L12: =IFERROR((I12-J12)/I12*100,"") | M12: =IFERROR(I12/(E12/1000),"") | N12: =IFERROR(I12/(F12*G12),"") | O12: ='Benchmark détaillé'!L31 | P12: ='Benchmark détaillé'!L32 | Q12: =IFERROR(VLOOKUP(A12,'Discounts par marque'!$A:$G,4,FALSE),0) | R12: =IFERROR(VLOOKUP(A12,'Discounts par marque'!$A:$G,5,FALSE),0) | S12: =IFERROR(I12*(1-Q12/100),"") | T12: =IFERROR(S12/(F12*G12),"") | U12: =IFERROR(I12*(1-R12/100),"") | V12: =IFERROR(U12/(F12*G12),"") | W12: https://www.nutrimuscle.com/products/whey-native-isolate
A13: ='Benchmark détaillé'!M1 | B13: Whey Native Isolate 4kg | C13: ='Benchmark détaillé'!M4 | D13: ='Benchmark détaillé'!M10 | E13: ='Benchmark détaillé'!M5 | F13: ='Benchmark détaillé'!M15 | G13: ='Benchmark détaillé'!M13 | H13: ='Benchmark détaillé'!M21 | I13: ='Benchmark détaillé'!M22 | J13: ='Benchmark détaillé'!M23 | K13: =IFERROR((H13-I13)/H13*100,"") | L13: =IFERROR((I13-J13)/I13*100,"") | M13: =IFERROR(I13/(E13/1000),"") | N13: =IFERROR(I13/(F13*G13),"") | O13: ='Benchmark détaillé'!M31 | P13: ='Benchmark détaillé'!M32 | Q13: =IFERROR(VLOOKUP(A13,'Discounts par marque'!$A:$G,4,FALSE),0) | R13: =IFERROR(VLOOKUP(A13,'Discounts par marque'!$A:$G,5,FALSE),0) | S13: =IFERROR(I13*(1-Q13/100),"") | T13: =IFERROR(S13/(F13*G13),"") | U13: =IFERROR(I13*(1-R13/100),"") | V13: =IFERROR(U13/(F13*G13),"") | W13: https://www.nutrimuscle.com/products/whey-native-isolate
A14: ='Benchmark détaillé'!N1 | B14: Whey Native Concentrat 500g | C14: ='Benchmark détaillé'!N4 | D14: ='Benchmark détaillé'!N10 | E14: ='Benchmark détaillé'!N5 | F14: ='Benchmark détaillé'!N15 | G14: ='Benchmark détaillé'!N13 | H14: ='Benchmark détaillé'!N21 | I14: ='Benchmark détaillé'!N22 | J14: ='Benchmark détaillé'!N23 | K14: =IFERROR((H14-I14)/H14*100,"") | L14: =IFERROR((I14-J14)/I14*100,"") | M14: =IFERROR(I14/(E14/1000),"") | N14: =IFERROR(I14/(F14*G14),"") | O14: ='Benchmark détaillé'!N31 | P14: ='Benchmark détaillé'!N32 | Q14: =IFERROR(VLOOKUP(A14,'Discounts par marque'!$A:$G,4,FALSE),0) | R14: =IFERROR(VLOOKUP(A14,'Discounts par marque'!$A:$G,5,FALSE),0) | S14: =IFERROR(I14*(1-Q14/100),"") | T14: =IFERROR(S14/(F14*G14),"") | U14: =IFERROR(I14*(1-R14/100),"") | V14: =IFERROR(U14/(F14*G14),"") | W14: https://www.nutrimuscle.com/products/whey-native
A15: ='Benchmark détaillé'!O1 | B15: Whey Native Concentrat | C15: ='Benchmark détaillé'!O4 | D15: ='Benchmark détaillé'!O10 | E15: ='Benchmark détaillé'!O5 | F15: ='Benchmark détaillé'!O15 | G15: ='Benchmark détaillé'!O13 | H15: ='Benchmark détaillé'!O21 | I15: ='Benchmark détaillé'!O22 | J15: ='Benchmark détaillé'!O23 | K15: =IFERROR((H15-I15)/H15*100,"") | L15: =IFERROR((I15-J15)/I15*100,"") | M15: =IFERROR(I15/(E15/1000),"") | N15: =IFERROR(I15/(F15*G15),"") | O15: ='Benchmark détaillé'!O31 | P15: ='Benchmark détaillé'!O32 | Q15: =IFERROR(VLOOKUP(A15,'Discounts par marque'!$A:$G,4,FALSE),0) | R15: =IFERROR(VLOOKUP(A15,'Discounts par marque'!$A:$G,5,FALSE),0) | S15: =IFERROR(I15*(1-Q15/100),"") | T15: =IFERROR(S15/(F15*G15),"") | U15: =IFERROR(I15*(1-R15/100),"") | V15: =IFERROR(U15/(F15*G15),"") | W15: https://www.nutrimuscle.com/products/whey-concentree-native | X15: v1 avait 25.95€ (+46% correction)
A16: ='Benchmark détaillé'!P1 | B16: Whey Native Concentrat 2,25kg | C16: ='Benchmark détaillé'!P4 | D16: ='Benchmark détaillé'!P10 | E16: ='Benchmark détaillé'!P5 | F16: ='Benchmark détaillé'!P15 | G16: ='Benchmark détaillé'!P13 | H16: ='Benchmark détaillé'!P21 | I16: ='Benchmark détaillé'!P22 | J16: ='Benchmark détaillé'!P23 | K16: =IFERROR((H16-I16)/H16*100,"") | L16: =IFERROR((I16-J16)/I16*100,"") | M16: =IFERROR(I16/(E16/1000),"") | N16: =IFERROR(I16/(F16*G16),"") | O16: ='Benchmark détaillé'!P31 | P16: ='Benchmark détaillé'!P32 | Q16: =IFERROR(VLOOKUP(A16,'Discounts par marque'!$A:$G,4,FALSE),0) | R16: =IFERROR(VLOOKUP(A16,'Discounts par marque'!$A:$G,5,FALSE),0) | S16: =IFERROR(I16*(1-Q16/100),"") | T16: =IFERROR(S16/(F16*G16),"") | U16: =IFERROR(I16*(1-R16/100),"") | V16: =IFERROR(U16/(F16*G16),"") | W16: https://www.nutrimuscle.com/products/whey-native
A17: ='Benchmark détaillé'!Q1 | B17: Whey Native Concentrat 4kg | C17: ='Benchmark détaillé'!Q4 | D17: ='Benchmark détaillé'!Q10 | E17: ='Benchmark détaillé'!Q5 | F17: ='Benchmark détaillé'!Q15 | G17: ='Benchmark détaillé'!Q13 | H17: ='Benchmark détaillé'!Q21 | I17: ='Benchmark détaillé'!Q22 | J17: ='Benchmark détaillé'!Q23 | K17: =IFERROR((H17-I17)/H17*100,"") | L17: =IFERROR((I17-J17)/I17*100,"") | M17: =IFERROR(I17/(E17/1000),"") | N17: =IFERROR(I17/(F17*G17),"") | O17: ='Benchmark détaillé'!Q31 | P17: ='Benchmark détaillé'!Q32 | Q17: =IFERROR(VLOOKUP(A17,'Discounts par marque'!$A:$G,4,FALSE),0) | R17: =IFERROR(VLOOKUP(A17,'Discounts par marque'!$A:$G,5,FALSE),0) | S17: =IFERROR(I17*(1-Q17/100),"") | T17: =IFERROR(S17/(F17*G17),"") | U17: =IFERROR(I17*(1-R17/100),"") | V17: =IFERROR(U17/(F17*G17),"") | W17: https://www.nutrimuscle.com/products/whey-native
A18: ='Benchmark détaillé'!R1 | B18: Whey Isolate Native 900g | C18: ='Benchmark détaillé'!R4 | D18: ='Benchmark détaillé'!R10 | E18: ='Benchmark détaillé'!R5 | F18: ='Benchmark détaillé'!R15 | G18: ='Benchmark détaillé'!R13 | H18: ='Benchmark détaillé'!R21 | I18: ='Benchmark détaillé'!R22 | J18: ='Benchmark détaillé'!R23 | K18: =IFERROR((H18-I18)/H18*100,"") | L18: =IFERROR((I18-J18)/I18*100,"") | M18: =IFERROR(I18/(E18/1000),"") | N18: =IFERROR(I18/(F18*G18),"") | O18: ='Benchmark détaillé'!R31 | P18: ='Benchmark détaillé'!R32 | Q18: =IFERROR(VLOOKUP(A18,'Discounts par marque'!$A:$G,4,FALSE),0) | R18: =IFERROR(VLOOKUP(A18,'Discounts par marque'!$A:$G,5,FALSE),0) | S18: =IFERROR(I18*(1-Q18/100),"") | T18: =IFERROR(S18/(F18*G18),"") | U18: =IFERROR(I18*(1-R18/100),"") | V18: =IFERROR(U18/(F18*G18),"") | W18: https://nutriandco.com/fr/produits/whey-isolate-native
A19: ='Benchmark détaillé'!S1 | B19: Whey Concentrée Native 900g | C19: ='Benchmark détaillé'!S4 | D19: ='Benchmark détaillé'!S10 | E19: ='Benchmark détaillé'!S5 | F19: ='Benchmark détaillé'!S15 | G19: ='Benchmark détaillé'!S13 | H19: ='Benchmark détaillé'!S21 | I19: ='Benchmark détaillé'!S22 | J19: ='Benchmark détaillé'!S23 | K19: =IFERROR((H19-I19)/H19*100,"") | L19: =IFERROR((I19-J19)/I19*100,"") | M19: =IFERROR(I19/(E19/1000),"") | N19: =IFERROR(I19/(F19*G19),"") | O19: ='Benchmark détaillé'!S31 | P19: ='Benchmark détaillé'!S32 | Q19: =IFERROR(VLOOKUP(A19,'Discounts par marque'!$A:$G,4,FALSE),0) | R19: =IFERROR(VLOOKUP(A19,'Discounts par marque'!$A:$G,5,FALSE),0) | S19: =IFERROR(I19*(1-Q19/100),"") | T19: =IFERROR(S19/(F19*G19),"") | U19: =IFERROR(I19*(1-R19/100),"") | V19: =IFERROR(U19/(F19*G19),"") | W19: https://nutriandco.com/fr/produits/whey-native
A20: ='Benchmark détaillé'!T1 | B20: Whey Native 810g | C20: ='Benchmark détaillé'!T4 | D20: ='Benchmark détaillé'!T10 | E20: ='Benchmark détaillé'!T5 | F20: ='Benchmark détaillé'!T15 | G20: ='Benchmark détaillé'!T13 | H20: ='Benchmark détaillé'!T21 | I20: ='Benchmark détaillé'!T22 | J20: ='Benchmark détaillé'!T23 | K20: =IFERROR((H20-I20)/H20*100,"") | L20: =IFERROR((I20-J20)/I20*100,"") | M20: =IFERROR(I20/(E20/1000),"") | N20: =IFERROR(I20/(F20*G20),"") | O20: ='Benchmark détaillé'!T31 | P20: ='Benchmark détaillé'!T32 | Q20: =IFERROR(VLOOKUP(A20,'Discounts par marque'!$A:$G,4,FALSE),0) | R20: =IFERROR(VLOOKUP(A20,'Discounts par marque'!$A:$G,5,FALSE),0) | S20: =IFERROR(I20*(1-Q20/100),"") | T20: =IFERROR(S20/(F20*G20),"") | U20: =IFERROR(I20*(1-R20/100),"") | V20: =IFERROR(U20/(F20*G20),"") | W20: https://www.aqeelab-nutrition.fr/products/whey-native-fabriquee-en-france-lait-francais
A21: ='Benchmark détaillé'!U1 | B21: Iso Zero 100% Whey Protéine 500g | C21: ='Benchmark détaillé'!U4 | D21: ='Benchmark détaillé'!U10 | E21: ='Benchmark détaillé'!U5 | F21: ='Benchmark détaillé'!U15 | G21: ='Benchmark détaillé'!U13 | H21: ='Benchmark détaillé'!U21 | I21: ='Benchmark détaillé'!U22 | J21: ='Benchmark détaillé'!U23 | K21: =IFERROR((H21-I21)/H21*100,"") | L21: =IFERROR((I21-J21)/I21*100,"") | M21: =IFERROR(I21/(E21/1000),"") | N21: =IFERROR(I21/(F21*G21),"") | O21: ='Benchmark détaillé'!U31 | P21: ='Benchmark détaillé'!U32 | Q21: =IFERROR(VLOOKUP(A21,'Discounts par marque'!$A:$G,4,FALSE),0) | R21: =IFERROR(VLOOKUP(A21,'Discounts par marque'!$A:$G,5,FALSE),0) | S21: =IFERROR(I21*(1-Q21/100),"") | T21: =IFERROR(S21/(F21*G21),"") | U21: =IFERROR(I21*(1-R21/100),"") | V21: =IFERROR(U21/(F21*G21),"") | W21: https://www.ericfavre.com/fr_fr/proteines/iso-zero-100-whey-proteine-cookies-cream-500g-p-194-o-1216.htm
A22: ='Benchmark détaillé'!V1 | B22: Iso Zero 100% Whey Protéine 1,5kg | C22: ='Benchmark détaillé'!V4 | D22: ='Benchmark détaillé'!V10 | E22: ='Benchmark détaillé'!V5 | F22: ='Benchmark détaillé'!V15 | G22: ='Benchmark détaillé'!V13 | H22: ='Benchmark détaillé'!V21 | I22: ='Benchmark détaillé'!V22 | J22: ='Benchmark détaillé'!V23 | K22: =IFERROR((H22-I22)/H22*100,"") | L22: =IFERROR((I22-J22)/I22*100,"") | M22: =IFERROR(I22/(E22/1000),"") | N22: =IFERROR(I22/(F22*G22),"") | O22: ='Benchmark détaillé'!V31 | P22: ='Benchmark détaillé'!V32 | Q22: =IFERROR(VLOOKUP(A22,'Discounts par marque'!$A:$G,4,FALSE),0) | R22: =IFERROR(VLOOKUP(A22,'Discounts par marque'!$A:$G,5,FALSE),0) | S22: =IFERROR(I22*(1-Q22/100),"") | T22: =IFERROR(S22/(F22*G22),"") | U22: =IFERROR(I22*(1-R22/100),"") | V22: =IFERROR(U22/(F22*G22),"") | W22: https://www.ericfavre.com/fr_fr/proteines/iso-zero-100-whey-proteine-choco-intense-1-5kg-p-194-o-1200.htm
A23: ='Benchmark détaillé'!W1 | B23: Iso Zero 100% Whey Protéine 2kg | C23: ='Benchmark détaillé'!W4 | D23: ='Benchmark détaillé'!W10 | E23: ='Benchmark détaillé'!W5 | F23: ='Benchmark détaillé'!W15 | G23: ='Benchmark détaillé'!W13 | H23: ='Benchmark détaillé'!W21 | I23: ='Benchmark détaillé'!W22 | J23: ='Benchmark détaillé'!W23 | K23: =IFERROR((H23-I23)/H23*100,"") | L23: =IFERROR((I23-J23)/I23*100,"") | M23: =IFERROR(I23/(E23/1000),"") | N23: =IFERROR(I23/(F23*G23),"") | O23: ='Benchmark détaillé'!W31 | P23: ='Benchmark détaillé'!W32 | Q23: =IFERROR(VLOOKUP(A23,'Discounts par marque'!$A:$G,4,FALSE),0) | R23: =IFERROR(VLOOKUP(A23,'Discounts par marque'!$A:$G,5,FALSE),0) | S23: =IFERROR(I23*(1-Q23/100),"") | T23: =IFERROR(S23/(F23*G23),"") | U23: =IFERROR(I23*(1-R23/100),"") | V23: =IFERROR(U23/(F23*G23),"") | W23: https://www.ericfavre.com/fr_fr/proteines/iso-zero-100-whey-proteine-chocotella-2kg-p-194-o-155.htm
A24: ='Benchmark détaillé'!X1 | B24: Whey Optimax Protein 500g | C24: ='Benchmark détaillé'!X4 | D24: ='Benchmark détaillé'!X10 | E24: ='Benchmark détaillé'!X5 | F24: ='Benchmark détaillé'!X15 | G24: ='Benchmark détaillé'!X13 | H24: ='Benchmark détaillé'!X21 | I24: ='Benchmark détaillé'!X22 | J24: ='Benchmark détaillé'!X23 | K24: =IFERROR((H24-I24)/H24*100,"") | L24: =IFERROR((I24-J24)/I24*100,"") | M24: =IFERROR(I24/(E24/1000),"") | N24: =IFERROR(I24/(F24*G24),"") | O24: ='Benchmark détaillé'!X31 | P24: ='Benchmark détaillé'!X32 | Q24: =IFERROR(VLOOKUP(A24,'Discounts par marque'!$A:$G,4,FALSE),0) | R24: =IFERROR(VLOOKUP(A24,'Discounts par marque'!$A:$G,5,FALSE),0) | S24: =IFERROR(I24*(1-Q24/100),"") | T24: =IFERROR(S24/(F24*G24),"") | U24: =IFERROR(I24*(1-R24/100),"") | V24: =IFERROR(U24/(F24*G24),"") | W24: https://www.ericfavre.com/fr_fr/proteines/whey-optimax-protein-biscuit-cookie-500g-p-622-o-1369.htm
A25: ='Benchmark détaillé'!Y1 | B25: Whey Optimax Protein 1,5kg | C25: ='Benchmark détaillé'!Y4 | D25: ='Benchmark détaillé'!Y10 | E25: ='Benchmark détaillé'!Y5 | F25: ='Benchmark détaillé'!Y15 | G25: ='Benchmark détaillé'!Y13 | H25: ='Benchmark détaillé'!Y21 | I25: ='Benchmark détaillé'!Y22 | J25: ='Benchmark détaillé'!Y23 | K25: =IFERROR((H25-I25)/H25*100,"") | L25: =IFERROR((I25-J25)/I25*100,"") | M25: =IFERROR(I25/(E25/1000),"") | N25: =IFERROR(I25/(F25*G25),"") | O25: ='Benchmark détaillé'!Y31 | P25: ='Benchmark détaillé'!Y32 | Q25: =IFERROR(VLOOKUP(A25,'Discounts par marque'!$A:$G,4,FALSE),0) | R25: =IFERROR(VLOOKUP(A25,'Discounts par marque'!$A:$G,5,FALSE),0) | S25: =IFERROR(I25*(1-Q25/100),"") | T25: =IFERROR(S25/(F25*G25),"") | U25: =IFERROR(I25*(1-R25/100),"") | V25: =IFERROR(U25/(F25*G25),"") | W25: https://www.ericfavre.com/fr_fr/proteines/whey-optimax-protein-chocolat-1-5kg-p-622-o-1370.htm
A26: ='Benchmark détaillé'!Z1 | B26: Whey Zero Protéine 2kg | C26: ='Benchmark détaillé'!Z4 | D26: ='Benchmark détaillé'!Z10 | E26: ='Benchmark détaillé'!Z5 | F26: ='Benchmark détaillé'!Z15 | G26: ='Benchmark détaillé'!Z13 | H26: ='Benchmark détaillé'!Z21 | I26: ='Benchmark détaillé'!Z22 | J26: ='Benchmark détaillé'!Z23 | K26: =IFERROR((H26-I26)/H26*100,"") | L26: =IFERROR((I26-J26)/I26*100,"") | M26: =IFERROR(I26/(E26/1000),"") | N26: =IFERROR(I26/(F26*G26),"") | O26: ='Benchmark détaillé'!Z31 | P26: ='Benchmark détaillé'!Z32 | Q26: =IFERROR(VLOOKUP(A26,'Discounts par marque'!$A:$G,4,FALSE),0) | R26: =IFERROR(VLOOKUP(A26,'Discounts par marque'!$A:$G,5,FALSE),0) | S26: =IFERROR(I26*(1-Q26/100),"") | T26: =IFERROR(S26/(F26*G26),"") | U26: =IFERROR(I26*(1-R26/100),"") | V26: =IFERROR(U26/(F26*G26),"") | W26: https://www.ericfavre.com/fr_fr/proteines/whey-zero-chocolat-2kg-p-517-o-1093.htm
A27: ='Benchmark détaillé'!AA1 | B27: Iso Fusion Protein Complex 750g | C27: ='Benchmark détaillé'!AA4 | D27: ='Benchmark détaillé'!AA10 | E27: ='Benchmark détaillé'!AA5 | F27: ='Benchmark détaillé'!AA15 | G27: ='Benchmark détaillé'!AA13 | H27: ='Benchmark détaillé'!AA21 | I27: ='Benchmark détaillé'!AA22 | J27: ='Benchmark détaillé'!AA23 | K27: =IFERROR((H27-I27)/H27*100,"") | L27: =IFERROR((I27-J27)/I27*100,"") | M27: =IFERROR(I27/(E27/1000),"") | N27: =IFERROR(I27/(F27*G27),"") | O27: ='Benchmark détaillé'!AA31 | P27: ='Benchmark détaillé'!AA32 | Q27: =IFERROR(VLOOKUP(A27,'Discounts par marque'!$A:$G,4,FALSE),0) | R27: =IFERROR(VLOOKUP(A27,'Discounts par marque'!$A:$G,5,FALSE),0) | S27: =IFERROR(I27*(1-Q27/100),"") | T27: =IFERROR(S27/(F27*G27),"") | U27: =IFERROR(I27*(1-R27/100),"") | V27: =IFERROR(U27/(F27*G27),"") | W27: https://www.ericfavre.com/fr_fr/proteines/iso-fusion-biscuit-cookie-750g-p-907-o-1924.htm
A28: ='Benchmark détaillé'!AB1 | B28: Iso Fusion Protein Complex 2kg | C28: ='Benchmark détaillé'!AB4 | D28: ='Benchmark détaillé'!AB10 | E28: ='Benchmark détaillé'!AB5 | F28: ='Benchmark détaillé'!AB15 | G28: ='Benchmark détaillé'!AB13 | H28: ='Benchmark détaillé'!AB21 | I28: ='Benchmark détaillé'!AB22 | J28: ='Benchmark détaillé'!AB23 | K28: =IFERROR((H28-I28)/H28*100,"") | L28: =IFERROR((I28-J28)/I28*100,"") | M28: =IFERROR(I28/(E28/1000),"") | N28: =IFERROR(I28/(F28*G28),"") | O28: ='Benchmark détaillé'!AB31 | P28: ='Benchmark détaillé'!AB32 | Q28: =IFERROR(VLOOKUP(A28,'Discounts par marque'!$A:$G,4,FALSE),0) | R28: =IFERROR(VLOOKUP(A28,'Discounts par marque'!$A:$G,5,FALSE),0) | S28: =IFERROR(I28*(1-Q28/100),"") | T28: =IFERROR(S28/(F28*G28),"") | U28: =IFERROR(I28*(1-R28/100),"") | V28: =IFERROR(U28/(F28*G28),"") | W28: https://www.ericfavre.com/fr_fr/proteines/iso-fusion-biscuit-cookie-2kg-p-907-o-1925.htm
A29: ='Benchmark détaillé'!AC1 | B29: Pure Isolate 750g | C29: ='Benchmark détaillé'!AC4 | D29: ='Benchmark détaillé'!AC10 | E29: ='Benchmark détaillé'!AC5 | F29: ='Benchmark détaillé'!AC15 | G29: ='Benchmark détaillé'!AC13 | H29: ='Benchmark détaillé'!AC21 | I29: ='Benchmark détaillé'!AC22 | J29: ='Benchmark détaillé'!AC23 | K29: =IFERROR((H29-I29)/H29*100,"") | L29: =IFERROR((I29-J29)/I29*100,"") | M29: =IFERROR(I29/(E29/1000),"") | N29: =IFERROR(I29/(F29*G29),"") | O29: ='Benchmark détaillé'!AC31 | P29: ='Benchmark détaillé'!AC32 | Q29: =IFERROR(VLOOKUP(A29,'Discounts par marque'!$A:$G,4,FALSE),0) | R29: =IFERROR(VLOOKUP(A29,'Discounts par marque'!$A:$G,5,FALSE),0) | S29: =IFERROR(I29*(1-Q29/100),"") | T29: =IFERROR(S29/(F29*G29),"") | U29: =IFERROR(I29*(1-R29/100),"") | V29: =IFERROR(U29/(F29*G29),"") | W29: https://www.eafit.com/eafit-pure-isolate.html
A30: ='Benchmark détaillé'!AD1 | B30: Pure Isolate Premium 750g | C30: ='Benchmark détaillé'!AD4 | D30: ='Benchmark détaillé'!AD10 | E30: ='Benchmark détaillé'!AD5 | F30: ='Benchmark détaillé'!AD15 | G30: ='Benchmark détaillé'!AD13 | H30: ='Benchmark détaillé'!AD21 | I30: ='Benchmark détaillé'!AD22 | J30: ='Benchmark détaillé'!AD23 | K30: =IFERROR((H30-I30)/H30*100,"") | L30: =IFERROR((I30-J30)/I30*100,"") | M30: =IFERROR(I30/(E30/1000),"") | N30: =IFERROR(I30/(F30*G30),"") | O30: ='Benchmark détaillé'!AD31 | P30: ='Benchmark détaillé'!AD32 | Q30: =IFERROR(VLOOKUP(A30,'Discounts par marque'!$A:$G,4,FALSE),0) | R30: =IFERROR(VLOOKUP(A30,'Discounts par marque'!$A:$G,5,FALSE),0) | S30: =IFERROR(I30*(1-Q30/100),"") | T30: =IFERROR(S30/(F30*G30),"") | U30: =IFERROR(I30*(1-R30/100),"") | V30: =IFERROR(U30/(F30*G30),"") | W30: https://www.eafit.com/eafit-pure-isolate-premium.html
A31: ='Benchmark détaillé'!AE1 | B31: Pure Whey Protein 750g | C31: ='Benchmark détaillé'!AE4 | D31: ='Benchmark détaillé'!AE10 | E31: ='Benchmark détaillé'!AE5 | F31: ='Benchmark détaillé'!AE15 | G31: ='Benchmark détaillé'!AE13 | H31: ='Benchmark détaillé'!AE21 | I31: ='Benchmark détaillé'!AE22 | J31: ='Benchmark détaillé'!AE23 | K31: =IFERROR((H31-I31)/H31*100,"") | L31: =IFERROR((I31-J31)/I31*100,"") | M31: =IFERROR(I31/(E31/1000),"") | N31: =IFERROR(I31/(F31*G31),"") | O31: ='Benchmark détaillé'!AE31 | P31: ='Benchmark détaillé'!AE32 | Q31: =IFERROR(VLOOKUP(A31,'Discounts par marque'!$A:$G,4,FALSE),0) | R31: =IFERROR(VLOOKUP(A31,'Discounts par marque'!$A:$G,5,FALSE),0) | S31: =IFERROR(I31*(1-Q31/100),"") | T31: =IFERROR(S31/(F31*G31),"") | U31: =IFERROR(I31*(1-R31/100),"") | V31: =IFERROR(U31/(F31*G31),"") | W31: https://www.eafit.com/eafit-pure-whey.html
A32: ='Benchmark détaillé'!AF1 | B32: Mega Whey Creatine Complex 750g | C32: ='Benchmark détaillé'!AF4 | D32: ='Benchmark détaillé'!AF10 | E32: ='Benchmark détaillé'!AF5 | F32: ='Benchmark détaillé'!AF15 | G32: ='Benchmark détaillé'!AF13 | H32: ='Benchmark détaillé'!AF21 | I32: ='Benchmark détaillé'!AF22 | J32: ='Benchmark détaillé'!AF23 | K32: =IFERROR((H32-I32)/H32*100,"") | L32: =IFERROR((I32-J32)/I32*100,"") | M32: =IFERROR(I32/(E32/1000),"") | N32: =IFERROR(I32/(F32*G32),"") | O32: ='Benchmark détaillé'!AF31 | P32: ='Benchmark détaillé'!AF32 | Q32: =IFERROR(VLOOKUP(A32,'Discounts par marque'!$A:$G,4,FALSE),0) | R32: =IFERROR(VLOOKUP(A32,'Discounts par marque'!$A:$G,5,FALSE),0) | S32: =IFERROR(I32*(1-Q32/100),"") | T32: =IFERROR(S32/(F32*G32),"") | U32: =IFERROR(I32*(1-R32/100),"") | V32: =IFERROR(U32/(F32*G32),"") | W32: https://www.eafit.com/eafit-megawhey.html
A33: ='Benchmark détaillé'!AG1 | B33: Pure Whey Protein 850g | C33: ='Benchmark détaillé'!AG4 | D33: ='Benchmark détaillé'!AG10 | E33: ='Benchmark détaillé'!AG5 | F33: ='Benchmark détaillé'!AG15 | G33: ='Benchmark détaillé'!AG13 | H33: ='Benchmark détaillé'!AG21 | I33: ='Benchmark détaillé'!AG22 | J33: ='Benchmark détaillé'!AG23 | K33: =IFERROR((H33-I33)/H33*100,"") | L33: =IFERROR((I33-J33)/I33*100,"") | M33: =IFERROR(I33/(E33/1000),"") | N33: =IFERROR(I33/(F33*G33),"") | O33: ='Benchmark détaillé'!AG31 | P33: ='Benchmark détaillé'!AG32 | Q33: =IFERROR(VLOOKUP(A33,'Discounts par marque'!$A:$G,4,FALSE),0) | R33: =IFERROR(VLOOKUP(A33,'Discounts par marque'!$A:$G,5,FALSE),0) | S33: =IFERROR(I33*(1-Q33/100),"") | T33: =IFERROR(S33/(F33*G33),"") | U33: =IFERROR(I33*(1-R33/100),"") | V33: =IFERROR(U33/(F33*G33),"") | W33: https://www.eafit.com/eafit-pure-whey.html
A34: ='Benchmark détaillé'!AH1 | B34: Pure Whey Protein 2.2kg | C34: ='Benchmark détaillé'!AH4 | D34: ='Benchmark détaillé'!AH10 | E34: ='Benchmark détaillé'!AH5 | F34: ='Benchmark détaillé'!AH15 | G34: ='Benchmark détaillé'!AH13 | H34: ='Benchmark détaillé'!AH21 | I34: ='Benchmark détaillé'!AH22 | J34: ='Benchmark détaillé'!AH23 | K34: =IFERROR((H34-I34)/H34*100,"") | L34: =IFERROR((I34-J34)/I34*100,"") | M34: =IFERROR(I34/(E34/1000),"") | N34: =IFERROR(I34/(F34*G34),"") | O34: ='Benchmark détaillé'!AH31 | P34: ='Benchmark détaillé'!AH32 | Q34: =IFERROR(VLOOKUP(A34,'Discounts par marque'!$A:$G,4,FALSE),0) | R34: =IFERROR(VLOOKUP(A34,'Discounts par marque'!$A:$G,5,FALSE),0) | S34: =IFERROR(I34*(1-Q34/100),"") | T34: =IFERROR(S34/(F34*G34),"") | U34: =IFERROR(I34*(1-R34/100),"") | V34: =IFERROR(U34/(F34*G34),"") | W34: https://www.eafit.com/eafit-pure-whey.html
A35: ='Benchmark détaillé'!AI1 | B35: Pure Whey Isolate 1kg | C35: ='Benchmark détaillé'!AI4 | D35: ='Benchmark détaillé'!AI10 | E35: ='Benchmark détaillé'!AI5 | F35: ='Benchmark détaillé'!AI15 | G35: ='Benchmark détaillé'!AI13 | H35: ='Benchmark détaillé'!AI21 | I35: ='Benchmark détaillé'!AI22 | J35: ='Benchmark détaillé'!AI23 | K35: =IFERROR((H35-I35)/H35*100,"") | L35: =IFERROR((I35-J35)/I35*100,"") | M35: =IFERROR(I35/(E35/1000),"") | N35: =IFERROR(I35/(F35*G35),"") | O35: ='Benchmark détaillé'!AI31 | P35: ='Benchmark détaillé'!AI32 | Q35: =IFERROR(VLOOKUP(A35,'Discounts par marque'!$A:$G,4,FALSE),0) | R35: =IFERROR(VLOOKUP(A35,'Discounts par marque'!$A:$G,5,FALSE),0) | S35: =IFERROR(I35*(1-Q35/100),"") | T35: =IFERROR(S35/(F35*G35),"") | U35: =IFERROR(I35*(1-R35/100),"") | V35: =IFERROR(U35/(F35*G35),"") | W35: https://www.bulk.com/fr/pure-whey-isolate-90.html | X35: Catalogue fictif majeur: 69.99€ barré vs 44.99€ réel (-36%)
A36: ='Benchmark détaillé'!AJ1 | B36: Pure Whey Isolate 2,5kg | C36: ='Benchmark détaillé'!AJ4 | D36: ='Benchmark détaillé'!AJ10 | E36: ='Benchmark détaillé'!AJ5 | F36: ='Benchmark détaillé'!AJ15 | G36: ='Benchmark détaillé'!AJ13 | H36: ='Benchmark détaillé'!AJ21 | I36: ='Benchmark détaillé'!AJ22 | J36: ='Benchmark détaillé'!AJ23 | K36: =IFERROR((H36-I36)/H36*100,"") | L36: =IFERROR((I36-J36)/I36*100,"") | M36: =IFERROR(I36/(E36/1000),"") | N36: =IFERROR(I36/(F36*G36),"") | O36: ='Benchmark détaillé'!AJ31 | P36: ='Benchmark détaillé'!AJ32 | Q36: =IFERROR(VLOOKUP(A36,'Discounts par marque'!$A:$G,4,FALSE),0) | R36: =IFERROR(VLOOKUP(A36,'Discounts par marque'!$A:$G,5,FALSE),0) | S36: =IFERROR(I36*(1-Q36/100),"") | T36: =IFERROR(S36/(F36*G36),"") | U36: =IFERROR(I36*(1-R36/100),"") | V36: =IFERROR(U36/(F36*G36),"") | W36: https://www.bulk.com/fr/pure-whey-isolate-90.html | X36: Catalogue fictif fort: 159.99€ vs 99.99€ réel (-37%)
A37: ='Benchmark détaillé'!AK1 | B37: Pure Whey Protein 1kg | C37: ='Benchmark détaillé'!AK4 | D37: ='Benchmark détaillé'!AK10 | E37: ='Benchmark détaillé'!AK5 | F37: ='Benchmark détaillé'!AK15 | G37: ='Benchmark détaillé'!AK13 | H37: ='Benchmark détaillé'!AK21 | I37: ='Benchmark détaillé'!AK22 | J37: ='Benchmark détaillé'!AK23 | K37: =IFERROR((H37-I37)/H37*100,"") | L37: =IFERROR((I37-J37)/I37*100,"") | M37: =IFERROR(I37/(E37/1000),"") | N37: =IFERROR(I37/(F37*G37),"") | O37: ='Benchmark détaillé'!AK31 | P37: ='Benchmark détaillé'!AK32 | Q37: =IFERROR(VLOOKUP(A37,'Discounts par marque'!$A:$G,4,FALSE),0) | R37: =IFERROR(VLOOKUP(A37,'Discounts par marque'!$A:$G,5,FALSE),0) | S37: =IFERROR(I37*(1-Q37/100),"") | T37: =IFERROR(S37/(F37*G37),"") | U37: =IFERROR(I37*(1-R37/100),"") | V37: =IFERROR(U37/(F37*G37),"") | W37: https://www.bulk.com/fr/pure-whey-protein-1.html | X37: Catalogue partiellement fictif: barré 37.99€ vs current 27.99€ vs marché 23.99€
A38: ='Benchmark détaillé'!AL1 | B38: Pure Whey Protein 2,5kg | C38: ='Benchmark détaillé'!AL4 | D38: ='Benchmark détaillé'!AL10 | E38: ='Benchmark détaillé'!AL5 | F38: ='Benchmark détaillé'!AL15 | G38: ='Benchmark détaillé'!AL13 | H38: ='Benchmark détaillé'!AL21 | I38: ='Benchmark détaillé'!AL22 | J38: ='Benchmark détaillé'!AL23 | K38: =IFERROR((H38-I38)/H38*100,"") | L38: =IFERROR((I38-J38)/I38*100,"") | M38: =IFERROR(I38/(E38/1000),"") | N38: =IFERROR(I38/(F38*G38),"") | O38: ='Benchmark détaillé'!AL31 | P38: ='Benchmark détaillé'!AL32 | Q38: =IFERROR(VLOOKUP(A38,'Discounts par marque'!$A:$G,4,FALSE),0) | R38: =IFERROR(VLOOKUP(A38,'Discounts par marque'!$A:$G,5,FALSE),0) | S38: =IFERROR(I38*(1-Q38/100),"") | T38: =IFERROR(S38/(F38*G38),"") | U38: =IFERROR(I38*(1-R38/100),"") | V38: =IFERROR(U38/(F38*G38),"") | W38: https://www.bulk.com/fr/pure-whey-protein-1.html | X38: Catalogue fictif: 84.99€ barré vs 64.99€ réel (-23%)
A39: ='Benchmark détaillé'!AM1 | B39: Pure Whey Protein 5kg | C39: ='Benchmark détaillé'!AM4 | D39: ='Benchmark détaillé'!AM10 | E39: ='Benchmark détaillé'!AM5 | F39: ='Benchmark détaillé'!AM15 | G39: ='Benchmark détaillé'!AM13 | H39: ='Benchmark détaillé'!AM21 | I39: ='Benchmark détaillé'!AM22 | J39: ='Benchmark détaillé'!AM23 | K39: =IFERROR((H39-I39)/H39*100,"") | L39: =IFERROR((I39-J39)/I39*100,"") | M39: =IFERROR(I39/(E39/1000),"") | N39: =IFERROR(I39/(F39*G39),"") | O39: ='Benchmark détaillé'!AM31 | P39: ='Benchmark détaillé'!AM32 | Q39: =IFERROR(VLOOKUP(A39,'Discounts par marque'!$A:$G,4,FALSE),0) | R39: =IFERROR(VLOOKUP(A39,'Discounts par marque'!$A:$G,5,FALSE),0) | S39: =IFERROR(I39*(1-Q39/100),"") | T39: =IFERROR(S39/(F39*G39),"") | U39: =IFERROR(I39*(1-R39/100),"") | V39: =IFERROR(U39/(F39*G39),"") | W39: https://www.bulk.com/fr/pure-whey-protein-1.html | X39: Catalogue fictif: 159.99€ vs 129.99€ payé (-19%)
A40: ='Benchmark détaillé'!AN1 | B40: Clear Whey Isolate 500g | C40: ='Benchmark détaillé'!AN4 | D40: ='Benchmark détaillé'!AN10 | E40: ='Benchmark détaillé'!AN5 | F40: ='Benchmark détaillé'!AN15 | G40: ='Benchmark détaillé'!AN13 | H40: ='Benchmark détaillé'!AN21 | I40: ='Benchmark détaillé'!AN22 | J40: ='Benchmark détaillé'!AN23 | K40: =IFERROR((H40-I40)/H40*100,"") | L40: =IFERROR((I40-J40)/I40*100,"") | M40: =IFERROR(I40/(E40/1000),"") | N40: =IFERROR(I40/(F40*G40),"") | O40: ='Benchmark détaillé'!AN31 | P40: ='Benchmark détaillé'!AN32 | Q40: =IFERROR(VLOOKUP(A40,'Discounts par marque'!$A:$G,4,FALSE),0) | R40: =IFERROR(VLOOKUP(A40,'Discounts par marque'!$A:$G,5,FALSE),0) | S40: =IFERROR(I40*(1-Q40/100),"") | T40: =IFERROR(S40/(F40*G40),"") | U40: =IFERROR(I40*(1-R40/100),"") | V40: =IFERROR(U40/(F40*G40),"") | W40: https://www.bulk.com/fr/clear-whey-isolate.html | X40: Catalogue 31.49€ barré vs 25.99€ payé (-17%). Marché 22.25€
...

Sheet Discounts par marque
A1: Marque | B1: 1ère cmd (%) | C1: Remise bas fourchette (%) | D1: Remise client standard (%) | E1: Remise client averti (%) | F1: Remise plafond observé (%) | G1: % prix réel vs catalogue | H1: Fréquence promo | I1: Codes (top 5) | J1: N codes sourcés | K1: Règles stacking | L1: Note | M1: Sources
A2: IMPULSE | B2: 10 | C2: 15 | D2: 15 | E2: 15 | F2: 15 | G2: 85 | H2: ponctuel | I2: LORENA 15% (@lorena) | J2: 1 | K2: 10% première commande ne stacke pas avec code ambassadeur; parrainage 15% sur 1ère commande + 10% parrain | L2: Politique -10% bienvenue homepage; codes ambassadeurs typiquement 15%. Pas de promo quasi-permanente publique. | M2: https://impulse-nutrition.fr https://impulse-nutrition.fr/pages/refer https://fr.hotdeals.com/code-promo/impulse-nutrition
